Workbook

Sheet 損失
A1: no | B1: v30_binder_damaged | C1: v30_combine_harvester_damaged | D1: v30_crop_harvester_damaged | E1: v30_tractor_damaged | F1: v30_ride_on_rice_transplanter_damaged | G1: v30_walk_rice_transplanter_damaged | H1: v30_grain_dryer_damaged | I1: v30_cultivator_damaged | J1: v30_power_tiller_damaged | K1: v30_brush_cutter_damaged
A2: 1 | F2: 1 | I2: 1 | K2: 2
A3: 7 | D3: 1 | K3: 1
A4: 8 | E4: 1 | F4: 1 | J4: 1 | K4: 1
A5: 9 | C5: 1 | G5: 1 | K5: 1
A6: 13 | E6: 1 | G6: 1 | K6: 1
A7: 17 | H7: 2 | J7: 1 | K7: 1
A8: 20 | B8: 1 | D8: 1 | F8: 1 | J8: 1
A9: 21 | F9: 1 | K9: 1
A10: 26 | G10: 1
A11: 28 | E11: 1 | F11: 1 | K11: 1
A12: 30 | E12: 1 | F12: 1 | J12: 1 | K12: 2
A13: 33 | E13: 1 | G13: 1
A14: 36 | K14: 1
A15: 37 | E15: 1 | F15: 1
A16: 42 | B16: 1 | D16: 1 | E16: 1 | F16: 1 | J16: 1 | K16: 2
A17: 45 | C17: 1 | E17: 1 | G17: 1 | H17: 1
A18: 47 | G18: 1 | H18: 2
A19: 49 | I19: 1 | K19: 1
A20: 52 | C20: 1 | E20: 1
A21: 55 | C21: 1 | E21: 1 | F21: 1 | H21: 1 | K21: 1
A22: 56 | E22: 1 | F22: 1 | H22: 1 | K22: 1
A23: 59 | E23: 1 | G23: 1 | K23: 1
A24: 60 | K24: 1
A25: 61 | K25: 1
A26: 65 | B26: 1 | D26: 1 | E26: 1 | F26: 1 | H26: 1 | J26: 1 | K26: 1
A27: 71 | J27: 1 | K27: 1
A28: 72 | C28: 1 | E28: 1 | F28: 1 | H28: 1 | I28: 1 | K28: 1
A29: 73 | I29: 1 | K29: 1
A30: 76 | B30: 2 | C30: 1 | D30: 2 | E30: 2 | G30: 2
A31: 82 | B31: 1 | E31: 1 | F31: 1
A32: 84 | B32: 1 | D32: 1 | E32: 1 | F32: 1 | J32: 1 | K32: 1
A33: 86 | C33: 1 | E33: 1 | F33: 1 | H33: 1 | K33: 3
A34: 89 | E34: 1 | F34: 1 | K34: 2
A35: 90 | K35: 1
A36: 92 | B36: 1 | D36: 1 | E36: 1 | G36: 1 | H36: 1 | K36: 1
A37: 93 | C37: 1 | F37: 1
A38: 94 | K38: 1
A39: 96 | C39: 1 | H39: 2
A40: 104 | F40: 1 | H40: 3
...

Sheet 残存
A1: no | B1: v31_binder_available | C1: v31_combine_harvester_available | D1: v31_crop_harvester_available | E1: v31_tractor_available | F1: v31_ride_on_rice_transplanter_available | G1: v31_walk_rice_transplanter_available | H1: v31_grain_dryer_available | I1: v31_cultivator_available | J1: v31_power_tiller_available | K1: v31_brush_cutter_available
A2: 1 | K2: 1
A3: 7 | K3: 1
A4: 8 | J4: 1 | K4: 1
A5: 10 | C5: 1 | E5: 1 | F5: 1
A6: 12 | I6: 1
A7: 13 | B7: 1
A8: 14 | D8: 1 | E8: 1 | K8: 2
A9: 15 | C9: 1 | E9: 1 | F9: 1 | H9: 1 | J9: 1 | K9: 1
A10: 19 | B10: 1 | E10: 1 | F10: 1 | G10: 1
A11: 20 | E11: 1
A12: 22 | K12: 1
A13: 24 | B13: 1 | D13: 1 | E13: 1 | G13: 1 | K13: 1
A14: 25 | C14: 1 | E14: 1 | F14: 1 | H14: 1 | I14: 1 | K14: 1
A15: 26 | B15: 1 | D15: 1 | E15: 1 | I15: 1 | J15: 1 | K15: 3
A16: 35 | I16: 1 | K16: 1
A17: 37 | K17: 1
A18: 39 | C18: 1 | E18: 1 | F18: 1 | H18: 1 | J18: 1 | K18: 1
A19: 40 | I19: 1 | K19: 1
A20: 41 | I20: 1 | K20: 1
A21: 43 | B21: 1 | D21: 1 | E21: 1 | G21: 1
A22: 44 | B22: 1 | C22: 1 | E22: 1 | F22: 1 | H22: 1 | I22: 1 | J22: 1 | K22: 1
A23: 47 | C23: 1 | E23: 1
A24: 50 | C24: 1 | E24: 2 | F24: 1 | H24: 2 | I24: 1 | J24: 1 | K24: 4
A25: 52 | F25: 1 | H25: 1 | J25: 1 | K25: 1
A26: 53 | J26: 1 | K26: 1
A27: 60 | K27: 1
A28: 64 | E28: 1 | F28: 1 | H28: 1 | J28: 1 | K28: 1
A29: 67 | C29: 1 | E29: 1 | F29: 1 | H29: 1 | J29: 1 | K29: 1
A30: 70 | C30: 1 | E30: 1 | F30: 1 | H30: 1 | J30: 1 | K30: 1
A31: 78 | C31: 1 | E31: 1 | F31: 1 | H31: 1
A32: 79 | E32: 1 | K32: 1
A33: 81 | C33: 1 | E33: 1 | F33: 1 | H33: 1
A34: 83 | E34: 1
A35: 87 | I35: 1 | K35: 1
A36: 91 | C36: 1 | E36: 1 | H36: 1 | K36: 1
A37: 93 | E37: 1
A38: 95 | C38: 1 | E38: 1 | F38: 1 | H38: 1 | J38: 1 | K38: 2
A39: 96 | E39: 1 | F39: 1 | J39: 1
A40: 97 | C40: 1 | E40: 1 | F40: 1 | H40: 1 | I40: 1 | K40: 1
...

Sheet noに関連づけ
A1: w3_no | B1: v30_binder_damaged | C1: v30_combine_harvester_damaged | D1: v30_crop_harvester_damaged | E1: v30_tractor_damaged | F1: v30_ride_on_rice_transplanter_damaged | G1: v30_walk_rice_transplanter_damaged | H1: v30_grain_dryer_damaged | I1: v30_cultivator_damaged | J1: v30_power_tiller_damaged | K1: v30_brush_cutter_damaged | M1: v31_binder_available | N1: v31_combine_harvester_available | O1: v31_crop_harvester_available | P1: v31_tractor_available | Q1: v31_ride_on_rice_transplanter_available | R1: v31_walk_rice_transplanter_available | S1: v31_grain_dryer_available | T1: v31_cultivator_available | U1: v31_power_tiller_available | V1: v31_brush_cutter_available
A2: 1 | B2: =_xlfn.XLOOKUP($A2, 損失!$A$2:$A$57, 損失!B$2:B$57, "") -> 0 | C2: =_xlfn.XLOOKUP($A2, 損失!$A$2:$A$57, 損失!C$2:C$57, "") -> 0 | D2: =_xlfn.XLOOKUP($A2, 損失!$A$2:$A$57, 損失!D$2:D$57, "") -> 0 | E2: =_xlfn.XLOOKUP($A2, 損失!$A$2:$A$57, 損失!E$2:E$57, "") -> 0 | F2: =_xlfn.XLOOKUP($A2, 損失!$A$2:$A$57, 損失!F$2:F$57, "") -> 1 | G2: =_xlfn.XLOOKUP($A2, 損失!$A$2:$A$57, 損失!G$2:G$57, "") -> 0 | H2: =_xlfn.XLOOKUP($A2, 損失!$A$2:$A$57, 損失!H$2:H$57, "") -> 0 | I2: =_xlfn.XLOOKUP($A2, 損失!$A$2:$A$57, 損失!I$2:I$57, "") -> 1 | ... L2: =_xlfn.XLOOKUP($A2, 損失!$A$2:$A$57, 損失!L$2:L$57, "") -> 0 | M2: =_xlfn.XLOOKUP($A2, 残存!$A$2:$A$54, 残存!B$2:B$54, "") -> 0 | N2: =_xlfn.XLOOKUP($A2, 残存!$A$2:$A$54, 残存!C$2:C$54, "") -> 0 | O2: =_xlfn.XLOOKUP($A2, 残存!$A$2:$A$54, 残存!D$2:D$54, "") -> 0 | P2: =_xlfn.XLOOKUP($A2, 残存!$A$2:$A$54, 残存!E$2:E$54, "") -> 0 | Q2: =_xlfn.XLOOKUP($A2, 残存!$A$2:$A$54, 残存!F$2:F$54, "") -> 0 | R2: =_xlfn.XLOOKUP($A2, 残存!$A$2:$A$54, 残存!G$2:G$54, "") -> 0 | S2: =_xlfn.XLOOKUP($A2, 残存!$A$2:$A$54, 残存!H$2:H$54, "") -> 0 | T2: =_xlfn.XLOOKUP($A2, 残存!$A$2:$A$54, 残存!I$2:I$54, "") -> 0 | ... W2: =_xlfn.XLOOKUP($A2, 残存!$A$2:$A$54, 残存!L$2:L$54, "") -> 0
A3: 2 | B3: =_xlfn.XLOOKUP($A3, 損失!$A$2:$A$57, 損失!B$2:B$57, "") | C3: =_xlfn.XLOOKUP($A3, 損失!$A$2:$A$57, 損失!C$2:C$57, "") | D3: =_xlfn.XLOOKUP($A3, 損失!$A$2:$A$57, 損失!D$2:D$57, "") | E3: =_xlfn.XLOOKUP($A3, 損失!$A$2:$A$57, 損失!E$2:E$57, "") | F3: =_xlfn.XLOOKUP($A3, 損失!$A$2:$A$57, 損失!F$2:F$57, "") | G3: =_xlfn.XLOOKUP($A3, 損失!$A$2:$A$57, 損失!G$2:G$57, "") | H3: =_xlfn.XLOOKUP($A3, 損失!$A$2:$A$57, 損失!H$2:H$57, "") | I3: =_xlfn.XLOOKUP($A3, 損失!$A$2:$A$57, 損失!I$2:I$57, "") | ... L3: =_xlfn.XLOOKUP($A3, 損失!$A$2:$A$57, 損失!L$2:L$57, "") | M3: =_xlfn.XLOOKUP($A3, 残存!$A$2:$A$54, 残存!B$2:B$54, "") | N3: =_xlfn.XLOOKUP($A3, 残存!$A$2:$A$54, 残存!C$2:C$54, "") | O3: =_xlfn.XLOOKUP($A3, 残存!$A$2:$A$54, 残存!D$2:D$54, "") | P3: =_xlfn.XLOOKUP($A3, 残存!$A$2:$A$54, 残存!E$2:E$54, "") | Q3: =_xlfn.XLOOKUP($A3, 残存!$A$2:$A$54, 残存!F$2:F$54, "") | R3: =_xlfn.XLOOKUP($A3, 残存!$A$2:$A$54, 残存!G$2:G$54, "") | S3: =_xlfn.XLOOKUP($A3, 残存!$A$2:$A$54, 残存!H$2:H$54, "") | T3: =_xlfn.XLOOKUP($A3, 残存!$A$2:$A$54, 残存!I$2:I$54, "") | ... W3: =_xlfn.XLOOKUP($A3, 残存!$A$2:$A$54, 残存!L$2:L$54, "")
A4: 3 | B4: =_xlfn.XLOOKUP($A4, 損失!$A$2:$A$57, 損失!B$2:B$57, "") | C4: =_xlfn.XLOOKUP($A4, 損失!$A$2:$A$57, 損失!C$2:C$57, "") | D4: =_xlfn.XLOOKUP($A4, 損失!$A$2:$A$57, 損失!D$2:D$57, "") | E4: =_xlfn.XLOOKUP($A4, 損失!$A$2:$A$57, 損失!E$2:E$57, "") | F4: =_xlfn.XLOOKUP($A4, 損失!$A$2:$A$57, 損失!F$2:F$57, "") | G4: =_xlfn.XLOOKUP($A4, 損失!$A$2:$A$57, 損失!G$2:G$57, "") | H4: =_xlfn.XLOOKUP($A4, 損失!$A$2:$A$57, 損失!H$2:H$57, "") | I4: =_xlfn.XLOOKUP($A4, 損失!$A$2:$A$57, 損失!I$2:I$57, "") | ... L4: =_xlfn.XLOOKUP($A4, 損失!$A$2:$A$57, 損失!L$2:L$57, "") | M4: =_xlfn.XLOOKUP($A4, 残存!$A$2:$A$54, 残存!B$2:B$54, "") | N4: =_xlfn.XLOOKUP($A4, 残存!$A$2:$A$54, 残存!C$2:C$54, "") | O4: =_xlfn.XLOOKUP($A4, 残存!$A$2:$A$54, 残存!D$2:D$54, "") | P4: =_xlfn.XLOOKUP($A4, 残存!$A$2:$A$54, 残存!E$2:E$54, "") | Q4: =_xlfn.XLOOKUP($A4, 残存!$A$2:$A$54, 残存!F$2:F$54, "") | R4: =_xlfn.XLOOKUP($A4, 残存!$A$2:$A$54, 残存!G$2:G$54, "") | S4: =_xlfn.XLOOKUP($A4, 残存!$A$2:$A$54, 残存!H$2:H$54, "") | T4: =_xlfn.XLOOKUP($A4, 残存!$A$2:$A$54, 残存!I$2:I$54, "") | ... W4: =_xlfn.XLOOKUP($A4, 残存!$A$2:$A$54, 残存!L$2:L$54, "")
A5: 4 | B5: =_xlfn.XLOOKUP($A5, 損失!$A$2:$A$57, 損失!B$2:B$57, "") | C5: =_xlfn.XLOOKUP($A5, 損失!$A$2:$A$57, 損失!C$2:C$57, "") | D5: =_xlfn.XLOOKUP($A5, 損失!$A$2:$A$57, 損失!D$2:D$57, "") | E5: =_xlfn.XLOOKUP($A5, 損失!$A$2:$A$57, 損失!E$2:E$57, "") | F5: =_xlfn.XLOOKUP($A5, 損失!$A$2:$A$57, 損失!F$2:F$57, "") | G5: =_xlfn.XLOOKUP($A5, 損失!$A$2:$A$57, 損失!G$2:G$57, "") | H5: =_xlfn.XLOOKUP($A5, 損失!$A$2:$A$57, 損失!H$2:H$57, "") | I5: =_xlfn.XLOOKUP($A5, 損失!$A$2:$A$57, 損失!I$2:I$57, "") | ... L5: =_xlfn.XLOOKUP($A5, 損失!$A$2:$A$57, 損失!L$2:L$57, "") | M5: =_xlfn.XLOOKUP($A5, 残存!$A$2:$A$54, 残存!B$2:B$54, "") | N5: =_xlfn.XLOOKUP($A5, 残存!$A$2:$A$54, 残存!C$2:C$54, "") | O5: =_xlfn.XLOOKUP($A5, 残存!$A$2:$A$54, 残存!D$2:D$54, "") | P5: =_xlfn.XLOOKUP($A5, 残存!$A$2:$A$54, 残存!E$2:E$54, "") | Q5: =_xlfn.XLOOKUP($A5, 残存!$A$2:$A$54, 残存!F$2:F$54, "") | R5: =_xlfn.XLOOKUP($A5, 残存!$A$2:$A$54, 残存!G$2:G$54, "") | S5: =_xlfn.XLOOKUP($A5, 残存!$A$2:$A$54, 残存!H$2:H$54, "") | T5: =_xlfn.XLOOKUP($A5, 残存!$A$2:$A$54, 残存!I$2:I$54, "") | ... W5: =_xlfn.XLOOKUP($A5, 残存!$A$2:$A$54, 残存!L$2:L$54, "")
A6: 5 | B6: =_xlfn.XLOOKUP($A6, 損失!$A$2:$A$57, 損失!B$2:B$57, "") | C6: =_xlfn.XLOOKUP($A6, 損失!$A$2:$A$57, 損失!C$2:C$57, "") | D6: =_xlfn.XLOOKUP($A6, 損失!$A$2:$A$57, 損失!D$2:D$57, "") | E6: =_xlfn.XLOOKUP($A6, 損失!$A$2:$A$57, 損失!E$2:E$57, "") | F6: =_xlfn.XLOOKUP($A6, 損失!$A$2:$A$57, 損失!F$2:F$57, "") | G6: =_xlfn.XLOOKUP($A6, 損失!$A$2:$A$57, 損失!G$2:G$57, "") | H6: =_xlfn.XLOOKUP($A6, 損失!$A$2:$A$57, 損失!H$2:H$57, "") | I6: =_xlfn.XLOOKUP($A6, 損失!$A$2:$A$57, 損失!I$2:I$57, "") | ... L6: =_xlfn.XLOOKUP($A6, 損失!$A$2:$A$57, 損失!L$2:L$57, "") | M6: =_xlfn.XLOOKUP($A6, 残存!$A$2:$A$54, 残存!B$2:B$54, "") | N6: =_xlfn.XLOOKUP($A6, 残存!$A$2:$A$54, 残存!C$2:C$54, "") | O6: =_xlfn.XLOOKUP($A6, 残存!$A$2:$A$54, 残存!D$2:D$54, "") | P6: =_xlfn.XLOOKUP($A6, 残存!$A$2:$A$54, 残存!E$2:E$54, "") | Q6: =_xlfn.XLOOKUP($A6, 残存!$A$2:$A$54, 残存!F$2:F$54, "") | R6: =_xlfn.XLOOKUP($A6, 残存!$A$2:$A$54, 残存!G$2:G$54, "") | S6: =_xlfn.XLOOKUP($A6, 残存!$A$2:$A$54, 残存!H$2:H$54, "") | T6: =_xlfn.XLOOKUP($A6, 残存!$A$2:$A$54, 残存!I$2:I$54, "") | ... W6: =_xlfn.XLOOKUP($A6, 残存!$A$2:$A$54, 残存!L$2:L$54, "")
A7: 6 | B7: =_xlfn.XLOOKUP($A7, 損失!$A$2:$A$57, 損失!B$2:B$57, "") | C7: =_xlfn.XLOOKUP($A7, 損失!$A$2:$A$57, 損失!C$2:C$57, "") | D7: =_xlfn.XLOOKUP($A7, 損失!$A$2:$A$57, 損失!D$2:D$57, "") | E7: =_xlfn.XLOOKUP($A7, 損失!$A$2:$A$57, 損失!E$2:E$57, "") | F7: =_xlfn.XLOOKUP($A7, 損失!$A$2:$A$57, 損失!F$2:F$57, "") | G7: =_xlfn.XLOOKUP($A7, 損失!$A$2:$A$57, 損失!G$2:G$57, "") | H7: =_xlfn.XLOOKUP($A7, 損失!$A$2:$A$57, 損失!H$2:H$57, "") | I7: =_xlfn.XLOOKUP($A7, 損失!$A$2:$A$57, 損失!I$2:I$57, "") | ... L7: =_xlfn.XLOOKUP($A7, 損失!$A$2:$A$57, 損失!L$2:L$57, "") | M7: =_xlfn.XLOOKUP($A7, 残存!$A$2:$A$54, 残存!B$2:B$54, "") | N7: =_xlfn.XLOOKUP($A7, 残存!$A$2:$A$54, 残存!C$2:C$54, "") | O7: =_xlfn.XLOOKUP($A7, 残存!$A$2:$A$54, 残存!D$2:D$54, "") | P7: =_xlfn.XLOOKUP($A7, 残存!$A$2:$A$54, 残存!E$2:E$54, "") | Q7: =_xlfn.XLOOKUP($A7, 残存!$A$2:$A$54, 残存!F$2:F$54, "") | R7: =_xlfn.XLOOKUP($A7, 残存!$A$2:$A$54, 残存!G$2:G$54, "") | S7: =_xlfn.XLOOKUP($A7, 残存!$A$2:$A$54, 残存!H$2:H$54, "") | T7: =_xlfn.XLOOKUP($A7, 残存!$A$2:$A$54, 残存!I$2:I$54, "") | ... W7: =_xlfn.XLOOKUP($A7, 残存!$A$2:$A$54, 残存!L$2:L$54, "")
A8: 7 | B8: =_xlfn.XLOOKUP($A8, 損失!$A$2:$A$57, 損失!B$2:B$57, "") -> 0 | C8: =_xlfn.XLOOKUP($A8, 損失!$A$2:$A$57, 損失!C$2:C$57, "") -> 0 | D8: =_xlfn.XLOOKUP($A8, 損失!$A$2:$A$57, 損失!D$2:D$57, "") -> 1 | E8: =_xlfn.XLOOKUP($A8, 損失!$A$2:$A$57, 損失!E$2:E$57, "") -> 0 | F8: =_xlfn.XLOOKUP($A8, 損失!$A$2:$A$57, 損失!F$2:F$57, "") -> 0 | G8: =_xlfn.XLOOKUP($A8, 損失!$A$2:$A$57, 損失!G$2:G$57, "") -> 0 | H8: =_xlfn.XLOOKUP($A8, 損失!$A$2:$A$57, 損失!H$2:H$57, "") -> 0 | I8: =_xlfn.XLOOKUP($A8, 損失!$A$2:$A$57, 損失!I$2:I$57, "") -> 0 | ... L8: =_xlfn.XLOOKUP($A8, 損失!$A$2:$A$57, 損失!L$2:L$57, "") -> 0 | M8: =_xlfn.XLOOKUP($A8, 残存!$A$2:$A$54, 残存!B$2:B$54, "") -> 0 | N8: =_xlfn.XLOOKUP($A8, 残存!$A$2:$A$54, 残存!C$2:C$54, "") -> 0 | O8: =_xlfn.XLOOKUP($A8, 残存!$A$2:$A$54, 残存!D$2:D$54, "") -> 0 | P8: =_xlfn.XLOOKUP($A8, 残存!$A$2:$A$54, 残存!E$2:E$54, "") -> 0 | Q8: =_xlfn.XLOOKUP($A8, 残存!$A$2:$A$54, 残存!F$2:F$54, "") -> 0 | R8: =_xlfn.XLOOKUP($A8, 残存!$A$2:$A$54, 残存!G$2:G$54, "") -> 0 | S8: =_xlfn.XLOOKUP($A8, 残存!$A$2:$A$54, 残存!H$2:H$54, "") -> 0 | T8: =_xlfn.XLOOKUP($A8, 残存!$A$2:$A$54, 残存!I$2:I$54, "") -> 0 | ... W8: =_xlfn.XLOOKUP($A8, 残存!$A$2:$A$54, 残存!L$2:L$54, "") -> 0
A9: 8 | B9: =_xlfn.XLOOKUP($A9, 損失!$A$2:$A$57, 損失!B$2:B$57, "") -> 0 | C9: =_xlfn.XLOOKUP($A9, 損失!$A$2:$A$57, 損失!C$2:C$57, "") -> 0 | D9: =_xlfn.XLOOKUP($A9, 損失!$A$2:$A$57, 損失!D$2:D$57, "") -> 0 | E9: =_xlfn.XLOOKUP($A9, 損失!$A$2:$A$57, 損失!E$2:E$57, "") -> 1 | F9: =_xlfn.XLOOKUP($A9, 損失!$A$2:$A$57, 損失!F$2:F$57, "") -> 1 | G9: =_xlfn.XLOOKUP($A9, 損失!$A$2:$A$57, 損失!G$2:G$57, "") -> 0 | H9: =_xlfn.XLOOKUP($A9, 損失!$A$2:$A$57, 損失!H$2:H$57, "") -> 0 | I9: =_xlfn.XLOOKUP($A9, 損失!$A$2:$A$57, 損失!I$2:I$57, "") -> 0 | ... L9: =_xlfn.XLOOKUP($A9, 損失!$A$2:$A$57, 損失!L$2:L$57, "") -> 0 | M9: =_xlfn.XLOOKUP($A9, 残存!$A$2:$A$54, 残存!B$2:B$54, "") -> 0 | N9: =_xlfn.XLOOKUP($A9, 残存!$A$2:$A$54, 残存!C$2:C$54, "") -> 0 | O9: =_xlfn.XLOOKUP($A9, 残存!$A$2:$A$54, 残存!D$2:D$54, "") -> 0 | P9: =_xlfn.XLOOKUP($A9, 残存!$A$2:$A$54, 残存!E$2:E$54, "") -> 0 | Q9: =_xlfn.XLOOKUP($A9, 残存!$A$2:$A$54, 残存!F$2:F$54, "") -> 0 | R9: =_xlfn.XLOOKUP($A9, 残存!$A$2:$A$54, 残存!G$2:G$54, "") -> 0 | S9: =_xlfn.XLOOKUP($A9, 残存!$A$2:$A$54, 残存!H$2:H$54, "") -> 0 | T9: =_xlfn.XLOOKUP($A9, 残存!$A$2:$A$54, 残存!I$2:I$54, "") -> 0 | ... W9: =_xlfn.XLOOKUP($A9, 残存!$A$2:$A$54, 残存!L$2:L$54, "") -> 0
A10: 9 | B10: =_xlfn.XLOOKUP($A10, 損失!$A$2:$A$57, 損失!B$2:B$57, "") -> 0 | C10: =_xlfn.XLOOKUP($A10, 損失!$A$2:$A$57, 損失!C$2:C$57, "") -> 1 | D10: =_xlfn.XLOOKUP($A10, 損失!$A$2:$A$57, 損失!D$2:D$57, "") -> 0 | E10: =_xlfn.XLOOKUP($A10, 損失!$A$2:$A$57, 損失!E$2:E$57, "") -> 0 | F10: =_xlfn.XLOOKUP($A10, 損失!$A$2:$A$57, 損失!F$2:F$57, "") -> 0 | G10: =_xlfn.XLOOKUP($A10, 損失!$A$2:$A$57, 損失!G$2:G$57, "") -> 1 | H10: =_xlfn.XLOOKUP($A10, 損失!$A$2:$A$57, 損失!H$2:H$57, "") -> 0 | I10: =_xlfn.XLOOKUP($A10, 損失!$A$2:$A$57, 損失!I$2:I$57, "") -> 0 | ... L10: =_xlfn.XLOOKUP($A10, 損失!$A$2:$A$57, 損失!L$2:L$57, "") -> 0 | M10: =_xlfn.XLOOKUP($A10, 残存!$A$2:$A$54, 残存!B$2:B$54, "") | N10: =_xlfn.XLOOKUP($A10, 残存!$A$2:$A$54, 残存!C$2:C$54, "") | O10: =_xlfn.XLOOKUP($A10, 残存!$A$2:$A$54, 残存!D$2:D$54, "") | P10: =_xlfn.XLOOKUP($A10, 残存!$A$2:$A$54, 残存!E$2:E$54, "") | Q10: =_xlfn.XLOOKUP($A10, 残存!$A$2:$A$54, 残存!F$2:F$54, "") | R10: =_xlfn.XLOOKUP($A10, 残存!$A$2:$A$54, 残存!G$2:G$54, "") | S10: =_xlfn.XLOOKUP($A10, 残存!$A$2:$A$54, 残存!H$2:H$54, "") | T10: =_xlfn.XLOOKUP($A10, 残存!$A$2:$A$54, 残存!I$2:I$54, "") | ... W10: =_xlfn.XLOOKUP($A10, 残存!$A$2:$A$54, 残存!L$2:L$54, "")
A11: 10 | B11: =_xlfn.XLOOKUP($A11, 損失!$A$2:$A$57, 損失!B$2:B$57, "") | C11: =_xlfn.XLOOKUP($A11, 損失!$A$2:$A$57, 損失!C$2:C$57, "") | D11: =_xlfn.XLOOKUP($A11, 損失!$A$2:$A$57, 損失!D$2:D$57, "") | E11: =_xlfn.XLOOKUP($A11, 損失!$A$2:$A$57, 損失!E$2:E$57, "") | F11: =_xlfn.XLOOKUP($A11, 損失!$A$2:$A$57, 損失!F$2:F$57, "") | G11: =_xlfn.XLOOKUP($A11, 損失!$A$2:$A$57, 損失!G$2:G$57, "") | H11: =_xlfn.XLOOKUP($A11, 損失!$A$2:$A$57, 損失!H$2:H$57, "") | I11: =_xlfn.XLOOKUP($A11, 損失!$A$2:$A$57, 損失!I$2:I$57, "") | ... L11: =_xlfn.XLOOKUP($A11, 損失!$A$2:$A$57, 損失!L$2:L$57, "") | M11: =_xlfn.XLOOKUP($A11, 残存!$A$2:$A$54, 残存!B$2:B$54, "") -> 0 | N11: =_xlfn.XLOOKUP($A11, 残存!$A$2:$A$54, 残存!C$2:C$54, "") -> 1 | O11: =_xlfn.XLOOKUP($A11, 残存!$A$2:$A$54, 残存!D$2:D$54, "") -> 0 | P11: =_xlfn.XLOOKUP($A11, 残存!$A$2:$A$54, 残存!E$2:E$54, "") -> 1 | Q11: =_xlfn.XLOOKUP($A11, 残存!$A$2:$A$54, 残存!F$2:F$54, "") -> 1 | R11: =_xlfn.XLOOKUP($A11, 残存!$A$2:$A$54, 残存!G$2:G$54, "") -> 0 | S11: =_xlfn.XLOOKUP($A11, 残存!$A$2:$A$54, 残存!H$2:H$54, "") -> 0 | T11: =_xlfn.XLOOKUP($A11, 残存!$A$2:$A$54, 残存!I$2:I$54, "") -> 0 | ... W11: =_xlfn.XLOOKUP($A11, 残存!$A$2:$A$54, 残存!L$2:L$54, "") -> 0
A12: 11 | B12: =_xlfn.XLOOKUP($A12, 損失!$A$2:$A$57, 損失!B$2:B$57, "") | C12: =_xlfn.XLOOKUP($A12, 損失!$A$2:$A$57, 損失!C$2:C$57, "") | D12: =_xlfn.XLOOKUP($A12, 損失!$A$2:$A$57, 損失!D$2:D$57, "") | E12: =_xlfn.XLOOKUP($A12, 損失!$A$2:$A$57, 損失!E$2:E$57, "") | F12: =_xlfn.XLOOKUP($A12, 損失!$A$2:$A$57, 損失!F$2:F$57, "") | G12: =_xlfn.XLOOKUP($A12, 損失!$A$2:$A$57, 損失!G$2:G$57, "") | H12: =_xlfn.XLOOKUP($A12, 損失!$A$2:$A$57, 損失!H$2:H$57, "") | I12: =_xlfn.XLOOKUP($A12, 損失!$A$2:$A$57, 損失!I$2:I$57, "") | ... L12: =_xlfn.XLOOKUP($A12, 損失!$A$2:$A$57, 損失!L$2:L$57, "") | M12: =_xlfn.XLOOKUP($A12, 残存!$A$2:$A$54, 残存!B$2:B$54, "") | N12: =_xlfn.XLOOKUP($A12, 残存!$A$2:$A$54, 残存!C$2:C$54, "") | O12: =_xlfn.XLOOKUP($A12, 残存!$A$2:$A$54, 残存!D$2:D$54, "") | P12: =_xlfn.XLOOKUP($A12, 残存!$A$2:$A$54, 残存!E$2:E$54, "") | Q12: =_xlfn.XLOOKUP($A12, 残存!$A$2:$A$54, 残存!F$2:F$54, "") | R12: =_xlfn.XLOOKUP($A12, 残存!$A$2:$A$54, 残存!G$2:G$54, "") | S12: =_xlfn.XLOOKUP($A12, 残存!$A$2:$A$54, 残存!H$2:H$54, "") | T12: =_xlfn.XLOOKUP($A12, 残存!$A$2:$A$54, 残存!I$2:I$54, "") | ... W12: =_xlfn.XLOOKUP($A12, 残存!$A$2:$A$54, 残存!L$2:L$54, "")
A13: 12 | B13: =_xlfn.XLOOKUP($A13, 損失!$A$2:$A$57, 損失!B$2:B$57, "") | C13: =_xlfn.XLOOKUP($A13, 損失!$A$2:$A$57, 損失!C$2:C$57, "") | D13: =_xlfn.XLOOKUP($A13, 損失!$A$2:$A$57, 損失!D$2:D$57, "") | E13: =_xlfn.XLOOKUP($A13, 損失!$A$2:$A$57, 損失!E$2:E$57, "") | F13: =_xlfn.XLOOKUP($A13, 損失!$A$2:$A$57, 損失!F$2:F$57, "") | G13: =_xlfn.XLOOKUP($A13, 損失!$A$2:$A$57, 損失!G$2:G$57, "") | H13: =_xlfn.XLOOKUP($A13, 損失!$A$2:$A$57, 損失!H$2:H$57, "") | I13: =_xlfn.XLOOKUP($A13, 損失!$A$2:$A$57, 損失!I$2:I$57, "") | ... L13: =_xlfn.XLOOKUP($A13, 損失!$A$2:$A$57, 損失!L$2:L$57, "") | M13: =_xlfn.XLOOKUP($A13, 残存!$A$2:$A$54, 残存!B$2:B$54, "") -> 0 | N13: =_xlfn.XLOOKUP($A13, 残存!$A$2:$A$54, 残存!C$2:C$54, "") -> 0 | O13: =_xlfn.XLOOKUP($A13, 残存!$A$2:$A$54, 残存!D$2:D$54, "") -> 0 | P13: =_xlfn.XLOOKUP($A13, 残存!$A$2:$A$54, 残存!E$2:E$54, "") -> 0 | Q13: =_xlfn.XLOOKUP($A13, 残存!$A$2:$A$54, 残存!F$2:F$54, "") -> 0 | R13: =_xlfn.XLOOKUP($A13, 残存!$A$2:$A$54, 残存!G$2:G$54, "") -> 0 | S13: =_xlfn.XLOOKUP($A13, 残存!$A$2:$A$54, 残存!H$2:H$54, "") -> 0 | T13: =_xlfn.XLOOKUP($A13, 残存!$A$2:$A$54, 残存!I$2:I$54, "") -> 1 | ... W13: =_xlfn.XLOOKUP($A13, 残存!$A$2:$A$54, 残存!L$2:L$54, "") -> 0
... A187: 186 | B187: =_xlfn.XLOOKUP($A187, 損失!$A$2:$A$57, 損失!B$2:B$57, "") | C187: =_xlfn.XLOOKUP($A187, 損失!$A$2:$A$57, 損失!C$2:C$57, "") | D187: =_xlfn.XLOOKUP($A187, 損失!$A$2:$A$57, 損失!D$2:D$57, "") | E187: =_xlfn.XLOOKUP($A187, 損失!$A$2:$A$57, 損失!E$2:E$57, "") | F187: =_xlfn.XLOOKUP($A187, 損失!$A$2:$A$57, 損失!F$2:F$57, "") | G187: =_xlfn.XLOOKUP($A187, 損失!$A$2:$A$57, 損失!G$2:G$57, "") | H187: =_xlfn.XLOOKUP($A187, 損失!$A$2:$A$57, 損失!H$2:H$57, "") | I187: =_xlfn.XLOOKUP($A187, 損失!$A$2:$A$57, 損失!I$2:I$57, "") | ... L187: =_xlfn.XLOOKUP($A187, 損失!$A$2:$A$57, 損失!L$2:L$57, "") | M187: =_xlfn.XLOOKUP($A187, 残存!$A$2:$A$54, 残存!B$2:B$54, "") | N187: =_xlfn.XLOOKUP($A187, 残存!$A$2:$A$54, 残存!C$2:C$54, "") | O187: =_xlfn.XLOOKUP($A187, 残存!$A$2:$A$54, 残存!D$2:D$54, "") | P187: =_xlfn.XLOOKUP($A187, 残存!$A$2:$A$54, 残存!E$2:E$54, "") | Q187: =_xlfn.XLOOKUP($A187, 残存!$A$2:$A$54, 残存!F$2:F$54, "") | R187: =_xlfn.XLOOKUP($A187, 残存!$A$2:$A$54, 残存!G$2:G$54, "") | S187: =_xlfn.XLOOKUP($A187, 残存!$A$2:$A$54, 残存!H$2:H$54, "") | T187: =_xlfn.XLOOKUP($A187, 残存!$A$2:$A$54, 残存!I$2:I$54, "") | ... W187: =_xlfn.XLOOKUP($A187, 残存!$A$2:$A$54, 残存!L$2:L$54, "")
