Workbook

Sheet すべてのnameとidリスト
A1: 初出 | B1: id | C1: name | D1: address_w1 | E1: address_w2 | F1: district_w3 | G1: address_w4 | H1: district_w4
A2: w1 | B2: 1 | C2: 岩本松治 | D2: 七ヶ浜町湊浜2-9-1 | E2: =_xlfn.XLOOKUP(C2, idつけ作業用!E$2:E$177, idつけ作業用!H$2:H$177, "") -> 湊浜二丁目９番地の１ | F2: 湊浜 | G2: 七ヶ浜町湊浜二-九-一 | H2: 湊浜
A3: w1 | B3: 2 | C3: 鈴木清弘 | D3: 七ヶ浜町湊浜1-4-4 | E3: =_xlfn.XLOOKUP(C3, idつけ作業用!E$2:E$177, idつけ作業用!H$2:H$177, "") -> 湊浜一丁目４番地の４ | F3: 湊浜 | G3: 七ヶ浜町湊浜一-四-四 | H3: 湊浜
A4: w1 | B4: 3 | C4: 鈴木益幸 | D4: 七ヶ浜町湊浜1-5-3 | E4: =_xlfn.XLOOKUP(C4, idつけ作業用!E$2:E$177, idつけ作業用!H$2:H$177, "") -> 湊浜一丁目５番地の３ | F4: 湊浜 | G4: 七ヶ浜町湊浜一-五-三 | H4: 湊浜
A5: w1 | B5: 4 | C5: 星嘉悦 | D5: 七ヶ浜町湊浜1-3-10 | E5: =_xlfn.XLOOKUP(C5, idつけ作業用!E$2:E$177, idつけ作業用!H$2:H$177, "") -> 湊浜一丁目３番地の１０
A6: w1 | B6: 5 | C6: 星新藏 | D6: 七ヶ浜町湊浜字熊野10-1 | E6: =_xlfn.XLOOKUP(C6, idつけ作業用!E$2:E$177, idつけ作業用!H$2:H$177, "") -> 湊浜字熊野１０番地の１ | F6: 湊浜 | G6: 七ヶ浜町湊浜字熊野十-一 | H6: 湊浜
A7: w1 | B7: 6 | C7: 渡辺ふじ江 | D7: 七ヶ浜町湊浜字砂山22 | E7: =_xlfn.XLOOKUP(C7, idつけ作業用!E$2:E$177, idつけ作業用!H$2:H$177, "") -> 湊浜字砂山２２番地 | F7: 湊浜 | G7: 七ヶ浜町湊浜字砂山二二 | H7: 湊浜
A8: w1 | B8: 7 | C8: 和泉とも子 | D8: 七ヶ浜町松ヶ浜字神明前13 | E8: =_xlfn.XLOOKUP(C8, idつけ作業用!E$2:E$177, idつけ作業用!H$2:H$177, "") -> 松ヶ浜字神明前１３番地 | F8: 松ヶ浜 | G8: 七ヶ浜町松ヶ浜字神明前一三 | H8: 松ヶ浜
A9: w1 | B9: 8 | C9: 梅津榮一 | D9: 七ヶ浜町松ヶ浜字浜屋敷33-1 | E9: =_xlfn.XLOOKUP(C9, idつけ作業用!E$2:E$177, idつけ作業用!H$2:H$177, "") -> 松ヶ浜字浜屋敷３３番地の１ | F9: 松ヶ浜 | G9: 七ヶ浜町松ヶ浜字浜屋敷三三-一 | H9: 松ヶ浜
A10: w1 | B10: 9 | C10: 加藤勝美 | D10: 七ヶ浜町松ヶ浜字浜屋敷45-1 | E10: =_xlfn.XLOOKUP(C10, idつけ作業用!E$2:E$177, idつけ作業用!H$2:H$177, "") -> 松ヶ浜字浜屋敷４５番地の１ | F10: 松ヶ浜 | G10: 七ヶ浜町松ヶ浜字浜屋敷四五-一 | H10: 松ヶ浜
A11: w1 | B11: 10 | C11: 加藤純一 | D11: 七ヶ浜町松ヶ浜字神明前6-1 | E11: =_xlfn.XLOOKUP(C11, idつけ作業用!E$2:E$177, idつけ作業用!H$2:H$177, "") -> 七ヶ浜町吉田浜字野山１番地の２七ヶ浜第１スポーツ広場応急仮設住宅 | F11: 松ヶ浜 | G11: 七ヶ浜町松ヶ浜字神明前六-一 | H11: 松ヶ浜
A12: w1 | B12: 11 | C12: 加藤信勝 | D12: 七ヶ浜町松ヶ浜字長根6-1 | E12: =_xlfn.XLOOKUP(C12, idつけ作業用!E$2:E$177, idつけ作業用!H$2:H$177, "") -> 松ヶ浜字長根６－１ | F12: 松ヶ浜 | G12: 七ヶ浜町松ヶ浜字長根六-一 | H12: 松ヶ浜
A13: w1 | B13: 12 | C13: 加藤壽治 | D13: 七ヶ浜町松ヶ浜字謡36-12 | E13: =_xlfn.XLOOKUP(C13, idつけ作業用!E$2:E$177, idつけ作業用!H$2:H$177, "") -> 松ヶ浜字謡３６番地の１２ | F13: 松ヶ浜 | G13: 七ヶ浜町松ヶ浜字謡三六-一二 | H13: 松ヶ浜
A14: w1 | B14: 13 | C14: 紀野國正勝 | D14: 七ヶ浜町松ヶ浜字坂口３4-1 | E14: =_xlfn.XLOOKUP(C14, idつけ作業用!E$2:E$177, idつけ作業用!H$2:H$177, "") -> 松ヶ浜字坂口３４番地の１ | F14: 松ヶ浜 | G14: 七ヶ浜町松ヶ浜字坂口三四-一 | H14: 松ヶ浜
A15: w1 | B15: 14 | C15: 後藤忠男 | D15: 七ヶ浜町松ヶ浜字浜屋敷８５ | E15: =_xlfn.XLOOKUP(C15, idつけ作業用!E$2:E$177, idつけ作業用!H$2:H$177, "") -> 松ヶ浜字浜屋敷８５番地 | G15: 七ヶ浜町松ヶ浜字浜屋敷八五 | H15: 松ヶ浜
A16: w1 | B16: 15 | C16: 櫻井富士男 | D16: 七ヶ浜町松ヶ浜字謡33-7 | E16: =_xlfn.XLOOKUP(C16, idつけ作業用!E$2:E$177, idつけ作業用!H$2:H$177, "") -> 松ヶ浜字謡３３番地の７ | F16: 松ヶ浜 | G16: 七ヶ浜町松ヶ浜字謡三三-七 | H16: 松ヶ浜
A17: w1 | B17: 16 | C17: 佐藤新太郎 | D17: 七ヶ浜町松ヶ浜字浜屋敷８２ | E17: =_xlfn.XLOOKUP(C17, idつけ作業用!E$2:E$177, idつけ作業用!H$2:H$177, "") | F17: 松ヶ浜 | G17: 七ヶ浜町松ヶ浜字浜屋敷八二 | H17: 松ヶ浜
A18: w1 | B18: 17 | C18: 鈴木吉雄 | D18: 七ヶ浜町松ヶ浜字神明裏48-2 | E18: =_xlfn.XLOOKUP(C18, idつけ作業用!E$2:E$177, idつけ作業用!H$2:H$177, "") -> 松ヶ浜字神明裏４８番地の２ | F18: 松ヶ浜 | G18: 七ヶ浜町松ヶ浜字神明裏四八-二 | H18: 松ヶ浜
A19: w1 | B19: 18 | C19: 鈴木幸一 | D19: 七ヶ浜町松ヶ浜字神明前2-3 | E19: =_xlfn.XLOOKUP(C19, idつけ作業用!E$2:E$177, idつけ作業用!H$2:H$177, "") -> 松ヶ浜字神明前２番地の３ | F19: 松ヶ浜 | G19: 七ヶ浜町松ヶ浜字神明前二-三 | H19: 松ヶ浜
A20: w1 | B20: 19 | C20: 鈴木七雄 | D20: 七ヶ浜町松ヶ浜字西沢田80 | E20: =_xlfn.XLOOKUP(C20, idつけ作業用!E$2:E$177, idつけ作業用!H$2:H$177, "") -> 松ヶ浜字西沢田８０番地 | F20: 松ヶ浜 | G20: 七ヶ浜町松ヶ浜字西沢田ハ〇 | H20: 松ヶ浜
A21: w1 | B21: 20 | C21: 鈴木庄衛 | D21: 七ヶ浜町松ヶ浜字西原6-1 | E21: =_xlfn.XLOOKUP(C21, idつけ作業用!E$2:E$177, idつけ作業用!H$2:H$177, "") -> 松ヶ浜字西原６番地の１ | F21: 松ヶ浜 | G21: 七ヶ浜町松ヶ浜字西原六-一 | H21: 松ヶ浜
A22: w1 | B22: 21 | C22: 鈴木しん | D22: 七ヶ浜町松ヶ浜字西沢田96-1 | E22: =_xlfn.XLOOKUP(C22, idつけ作業用!E$2:E$177, idつけ作業用!H$2:H$177, "") -> 松ヶ浜字西沢田９６番地の１
A23: w1 | B23: 22 | C23: 鈴木信也 | D23: 七ヶ浜町松ヶ浜字浜屋敷6 | E23: =_xlfn.XLOOKUP(C23, idつけ作業用!E$2:E$177, idつけ作業用!H$2:H$177, "") -> 松ヶ浜字浜屋敷６番地 | F23: 松ヶ浜 | G23: 七ヶ浜町松ヶ浜字浜屋敷六 | H23: 松ヶ浜
A24: w1 | B24: 23 | C24: 鈴木つい子 | D24: 七ヶ浜町松ヶ浜字神明裏47-1 | E24: =_xlfn.XLOOKUP(C24, idつけ作業用!E$2:E$177, idつけ作業用!H$2:H$177, "") -> 松ヶ浜字神明裏４７番地の１ | F24: 松ヶ浜 | G24: 七ヶ浜町松ヶ浜字神明裏四七-一 | H24: 松ヶ浜
A25: w1 | B25: 24 | C25: 鈴木藤助 | D25: 七ヶ浜町松ヶ浜字西原47-2 | E25: =_xlfn.XLOOKUP(C25, idつけ作業用!E$2:E$177, idつけ作業用!H$2:H$177, "") | F25: 松ヶ浜 | G25: 七ヶ浜町松ヶ浜字西原四七-二 | H25: 松ヶ浜
A26: w1 | B26: 25 | C26: 鈴木久 | D26: 七ヶ浜町松ヶ浜字長根1-3 | E26: =_xlfn.XLOOKUP(C26, idつけ作業用!E$2:E$177, idつけ作業用!H$2:H$177, "") -> 松ヶ浜字長根１番地の３ | F26: 松ヶ浜 | G26: 七ヶ浜町松ヶ浜字長根一-三 | H26: 松ヶ浜
A27: w1 | B27: 26 | C27: 鈴木平規 | D27: 七ヶ浜町松ヶ浜字浜屋敷104 | E27: =_xlfn.XLOOKUP(C27, idつけ作業用!E$2:E$177, idつけ作業用!H$2:H$177, "") -> 湊浜字砂山２６－１ | G27: 七ヶ浜町松ヶ浜字浜屋敷一〇四 | H27: 松ヶ浜
A28: w1 | B28: 27 | C28: 鈴木正人 | D28: 七ヶ浜町松ヶ浜字神明裏3-1 | E28: =_xlfn.XLOOKUP(C28, idつけ作業用!E$2:E$177, idつけ作業用!H$2:H$177, "") -> 松ヶ浜字神明裏３番地の１
A29: w1 | B29: 28 | C29: 鈴木豊 | D29: 七ヶ浜町松ヶ浜字謡22-5 | E29: =_xlfn.XLOOKUP(C29, idつけ作業用!E$2:E$177, idつけ作業用!H$2:H$177, "") -> 松ヶ浜字謡２２番地の５
A30: w1 | B30: 29 | C30: 太宰勉 | D30: 七ヶ浜町松ヶ浜字笹山86 | E30: =_xlfn.XLOOKUP(C30, idつけ作業用!E$2:E$177, idつけ作業用!H$2:H$177, "") | G30: 七ヶ浜町松ヶ浜字笹山ハ六 | H30: 松ヶ浜
A31: w1 | B31: 30 | C31: 太宰良子 | D31: 七ヶ浜町松ヶ浜字西原66 | E31: =_xlfn.XLOOKUP(C31, idつけ作業用!E$2:E$177, idつけ作業用!H$2:H$177, "") -> 松ヶ浜字西原６６番地 | F31: 松ヶ浜 | G31: 七ヶ浜町松ヶ浜字西原六六 | H31: 松ヶ浜
A32: w1 | B32: 31 | C32: 星昭男 | D32: 七ヶ浜町松ヶ浜字浜屋敷40 | E32: =_xlfn.XLOOKUP(C32, idつけ作業用!E$2:E$177, idつけ作業用!H$2:H$177, "")
A33: w1 | B33: 32 | C33: 星榮一 | D33: 七ヶ浜町松ヶ浜字神明裏38 | E33: =_xlfn.XLOOKUP(C33, idつけ作業用!E$2:E$177, idつけ作業用!H$2:H$177, "") -> 松ヶ浜字神明裏３８番地 | F33: 松ヶ浜 | G33: 七ヶ浜町松ヶ浜字神明裏三八 | H33: 松ヶ浜
A34: w1 | B34: 33 | C34: 星清勝 | D34: 七ヶ浜町松ヶ浜字神明裏29 | E34: =_xlfn.XLOOKUP(C34, idつけ作業用!E$2:E$177, idつけ作業用!H$2:H$177, "") | F34: 松ヶ浜 | G34: 七ヶ浜町松ヶ浜字笹山二－一 | H34: 松ヶ浜
A35: w1 | B35: 34 | C35: 星成 | D35: 七ヶ浜町松ヶ浜字浜屋敷78-1 | E35: =_xlfn.XLOOKUP(C35, idつけ作業用!E$2:E$177, idつけ作業用!H$2:H$177, "") -> 松ヶ浜字浜屋敷７８番地の１ | G35: 七ヶ浜町松ヶ浜字浜屋敷七八-一 | H35: 松ヶ浜
A36: w1 | B36: 35 | C36: 星辰男 | D36: 七ヶ浜町松ヶ浜字浜屋敷23 | E36: =_xlfn.XLOOKUP(C36, idつけ作業用!E$2:E$177, idつけ作業用!H$2:H$177, "") -> 松ヶ浜字浜屋敷２３番地 | F36: 松ヶ浜 | G36: 七ヶ浜町松ヶ浜字浜屋敷二三 | H36: 松ヶ浜
A37: w1 | B37: 36 | C37: 星博 | D37: 七ヶ浜町松ヶ浜字浜屋敷25 | E37: =_xlfn.XLOOKUP(C37, idつけ作業用!E$2:E$177, idつけ作業用!H$2:H$177, "") -> 松ヶ浜字浜屋敷２５番地 | F37: 松ヶ浜 | G37: 七ヶ浜町松ヶ浜字浜屋敷二五 | H37: 松ヶ浜
A38: w1 | B38: 37 | C38: 星兵喜 | D38: 七ヶ浜町松ヶ浜字浜屋敷9 | E38: =_xlfn.XLOOKUP(C38, idつけ作業用!E$2:E$177, idつけ作業用!H$2:H$177, "") -> 松ヶ浜字浜屋敷９番地 | F38: 松ヶ浜 | G38: 七ヶ浜町松ヶ浜字浜屋敷九 | H38: 松ヶ浜
A39: w1 | B39: 38 | C39: 星又一 | D39: 七ヶ浜町松ヶ浜字丸山26-1 | E39: =_xlfn.XLOOKUP(C39, idつけ作業用!E$2:E$177, idつけ作業用!H$2:H$177, "") -> 松ヶ浜字丸山２６番地の１ | F39: 松ヶ浜 | G39: 七ヶ浜町松ヶ浜字丸山二六-一 | H39: 松ヶ浜
A40: w1 | B40: 39 | C40: 星三千男 | D40: 七ヶ浜町松ヶ浜字浜屋敷22 | E40: =_xlfn.XLOOKUP(C40, idつけ作業用!E$2:E$177, idつけ作業用!H$2:H$177, "") -> 松ヶ浜字浜屋敷２２番地 | F40: 松ヶ浜 | G40: 七ヶ浜町松ヶ浜字浜屋敷二二 | H40: 松ヶ浜
...

Sheet idつけ作業用
A1: id_w1 | B1: name | C1: address_w1 | E1: name_w2 | F1: id_w2 | G1: w2_no | H1: address_w2
A2: 1 | B2: 岩本松治 | C2: 七ヶ浜町湊浜2-9-1 | E2: 岩本松治 | F2: =_xlfn.XLOOKUP(E2, B$2:B$231, A$2:A$231, 0) -> 1 | G2: 26 | H2: 湊浜二丁目９番地の１
A3: 2 | B3: 鈴木清弘 | C3: 七ヶ浜町湊浜1-4-4 | E3: 鈴木清弘 | F3: =_xlfn.XLOOKUP(E3, B$2:B$231, A$2:A$231, 0) -> 2 | G3: 75 | H3: 湊浜一丁目４番地の４
A4: 3 | B4: 鈴木益幸 | C4: 七ヶ浜町湊浜1-5-3 | E4: 鈴木益幸 | F4: =_xlfn.XLOOKUP(E4, B$2:B$231, A$2:A$231, 0) -> 3 | G4: 100 | H4: 湊浜一丁目５番地の３
A5: 4 | B5: 星嘉悦 | C5: 七ヶ浜町湊浜1-3-10 | E5: 星嘉悦 | F5: =_xlfn.XLOOKUP(E5, B$2:B$231, A$2:A$231, 0) -> 4 | G5: 118 | H5: 湊浜一丁目３番地の１０
A6: 5 | B6: 星新藏 | C6: 七ヶ浜町湊浜字熊野10-1 | E6: 星新藏 | F6: =_xlfn.XLOOKUP(E6, B$2:B$231, A$2:A$231, 0) -> 5 | G6: 114 | H6: 湊浜字熊野１０番地の１
A7: 6 | B7: 渡辺ふじ江 | C7: 七ヶ浜町湊浜字砂山22 | E7: 渡辺ふじ江 | F7: =_xlfn.XLOOKUP(E7, B$2:B$231, A$2:A$231, 0) -> 6 | G7: 158 | H7: 湊浜字砂山２２番地
A8: 7 | B8: 和泉とも子 | C8: 七ヶ浜町松ヶ浜字神明前13 | E8: 和泉とも子 | F8: =_xlfn.XLOOKUP(E8, B$2:B$231, A$2:A$231, 0) -> 7 | G8: 19 | H8: 松ヶ浜字神明前１３番地
A9: 8 | B9: 梅津榮一 | C9: 七ヶ浜町松ヶ浜字浜屋敷33-1 | E9: 梅津榮一 | F9: =_xlfn.XLOOKUP(E9, B$2:B$231, A$2:A$231, 0) -> 8 | G9: 28 | H9: 松ヶ浜字浜屋敷３３番地の１
A10: 9 | B10: 加藤勝美 | C10: 七ヶ浜町松ヶ浜字浜屋敷45-1 | E10: 加藤勝美 | F10: =_xlfn.XLOOKUP(E10, B$2:B$231, A$2:A$231, 0) -> 9 | G10: 35 | H10: 松ヶ浜字浜屋敷４５番地の１
A11: 10 | B11: 加藤純一 | C11: 七ヶ浜町松ヶ浜字神明前6-1 | E11: 加藤純一 | F11: =_xlfn.XLOOKUP(E11, B$2:B$231, A$2:A$231, 0) -> 10 | G11: 36 | H11: 七ヶ浜町吉田浜字野山１番地の２七ヶ浜第１スポーツ広場応急仮設住宅
A12: 11 | B12: 加藤信勝 | C12: 七ヶ浜町松ヶ浜字長根6-1 | E12: 加藤信勝 | F12: =_xlfn.XLOOKUP(E12, B$2:B$231, A$2:A$231, 0) -> 11 | G12: 176 | H12: 松ヶ浜字長根６－１
A13: 12 | B13: 加藤壽治 | C13: 七ヶ浜町松ヶ浜字謡36-12 | E13: 加藤壽治 | F13: =_xlfn.XLOOKUP(E13, B$2:B$231, A$2:A$231, 0) -> 12 | G13: 37 | H13: 松ヶ浜字謡３６番地の１２
... A167: 166 | B167: 赤間秋夫 | C167: 七ヶ浜町代ヶ崎浜字向田43-2 | E167: 高橋栄吉 | F167: =_xlfn.XLOOKUP(E167, B$2:B$231, A$2:A$231, 0) -> 230 | G167: 106 | H167: 東宮浜字小畑２３番地
A168: 167 | B168: 赤間陽 | C168: 七ヶ浜町代ヶ崎浜字向田52 | E168: 阿部平三郎 | F168: 231 | G168: 16 | H168: 七ヶ浜町吉田浜字野山１番地の２七ヶ浜第１スポーツ広場応急仮設住宅
A169: 168 | B169: 赤間胞治 | C169: 七ヶ浜町代ヶ崎浜字立花53 | E169: 齋藤喜良 | F169: 232 | G169: 44 | H169: 代ヶ崎浜字清水６２番地の３２
A170: 169 | B170: 赤間榮藏 | C170: 七ヶ浜町代ヶ崎浜字向田47 | E170: 佐藤たかを | F170: 233 | G170: 56 | H170: 代ヶ崎浜字立花２６番地
A171: 170 | B171: 赤間三五郎 | C171: 七ヶ浜町代ヶ崎浜字向田44-7 | E171: 佐藤久夫 | F171: 234 | G171: 60 | H171: 東宮浜字要害３２番地
A172: 171 | B172: 赤間長和 | C172: 七ヶ浜町代ヶ崎浜字向田54 | E172: 宍戸智 | F172: 235 | G172: 67 | H172: 塩釜市大日向町１－３４
A173: 172 | B173: 赤間竹喜 | C173: 七ヶ浜町代ヶ崎浜字向田44-2 | E173: 鈴木かつ子 | F173: 236 | G173: 73 | H173: 吉田浜字浜屋敷５６番地の２
A174: 173 | B174: 赤間長正 | C174: 七ヶ浜町代ヶ崎浜字向田43-1 | E174: 鈴木健司 | F174: 237 | G174: 78 | H174: 仙台市宮城野区福室三丁目２８－３８高砂ミューハイツ４０２号
A175: 174 | B175: 赤間日出男 | C175: 七ヶ浜町吉田浜字神明20-14 | E175: 星正 | F175: 238 | G175: 122 | H175: 七ヶ浜町吉田浜字野山５番地の９野外活動センター応急仮設住宅
A176: 175 | B176: 伊藤カヅ子 | C176: 七ヶ浜町代ヶ崎浜字西21-34 | E176: 渡邉勇一郎 | F176: 239 | G176: 159 | H176: 東宮浜字鶴ヶ湊２７番地の２
A177: 176 | B177: 伊藤定榮 | C177: 七ヶ浜町代ヶ崎浜字向田51 | E177: 星健二 | F177: 240 | G177: 169 | H177: 松ヶ浜字浜屋敷４０
A178: 177 | B178: 伊藤新一 | C178: 七ヶ浜町代ヶ崎浜字向田55-2
A179: 178 | B179: 齋藤喜二郎 | C179: 七ヶ浜町代ヶ崎浜字清水62-
A180: 179 | B180: 齋藤庄英 | C180: 七ヶ浜町代ヶ崎浜字影田6-4
A181: 180 | B181: 齋藤吉勝 | C181: 七ヶ浜町代ヶ崎浜字向田48
A182: 181 | B182: 佐藤勲 | C182: 七ヶ浜町代ヶ崎浜字向田42-1
A183: 182 | B183: 佐藤一郎 | C183: 七ヶ浜町代ヶ崎浜字向田49-1
A184: 183 | B184: 佐藤榮二 | C184: 七ヶ浜町代ヶ崎浜字八ヶ森31
A185: 184 | B185: 佐藤喜一 | C185: 七ヶ浜町代ヶ崎浜字立花26
A186: 185 | B186: 佐藤欣一 | C186: 七ヶ浜町代ヶ崎浜字向田44-3
A187: 186 | B187: 佐藤今朝衞 | C187: 七ヶ浜町代ヶ崎浜字向田４４－５
A188: 187 | B188: 佐藤幸志 | C188: 七ヶ浜町代ヶ崎浜字立花36
A189: 188 | B189: 佐藤つるよ | C189: 七ヶ浜町代ヶ崎浜字清水62-15
... A231: 230 | B231: 高橋栄吉 | C231: 七ヶ浜町東宮浜字小畑23
